Workbook

Sheet Disclaimer
B2: FLOORLINE · Multi-Account Tracker
B3: Read this first.
B5: DISCLAIMER
B6: Not financial, trading, or investment advice; educational calculation tool only.
B7: Not affiliated with, endorsed by, or sponsored by any prop firm, exchange (CME Group), or platform named.
B8: Prop firm rules change without notice. Every preset shows source_url, checked_date (2026-10-14 for v0.1) and page date; verify against the firm's current rules and your dashboard before trading. Presets are not guaranteed permanent or complete; "partial" presets require user input.
B9: The tracker relies on user-entered balances; it cannot see intraday order of events and can differ from the firm's real-time system. The firm's own calculation is authoritative.
B10: Spreadsheet floating-point arithmetic; values are rounded to cents conservatively.
B12: Spec: tracker v0.1.0 / oracle v0.2.0. No macros, no scripts, no external links or data connections.

Sheet How to use
B2: How to use
B3: REQUIREMENTS
B4: Microsoft Excel 2019, Excel 2021 or Microsoft 365 (uses MAXIFS and TEXTJOIN; Excel 2016 and earlier show #NAME? and are NOT supported).
B5: Tested: formulas were recalculated and checked in LibreOffice only. Excel and Google Sheets have NOT been tested; treat both as unverified until you confirm the results yourself.
B6: GOOGLE SHEETS IMPORT (UNTESTED)
B7: 1. Open drive.google.com, click New > File upload and choose Floorline-Tracker.xlsx.
B8: 2. Right-click the uploaded file > Open with > Google Sheets (or set Drive Settings > 'Convert uploads' before uploading).
B9: 3. In Sheets: File > Save as Google Sheets if it opened in Office-compatibility mode, then work in the converted copy.
B10: 4. Check the Accounts tab: Check column shows OK for filled rows and no cell shows #NAME? or #ERROR!. Compare a few results with your firm dashboard before relying on it.
B11: 5. Not verified in Sheets: whether sheet protection, dropdowns, data validation and colour rules survive the import. Pasted values can bypass dropdowns and validation; the formulas check many inputs, but not every possible mistake.
B12: DAILY ROUTINE
B13: 1. Accounts: one row per account (max 10). Enter Account ID and pick a Preset (or Manual). Read the Flags column.
... B26: Matching ignores letter case: account IDs must be unique ignoring case (p16 and P16 are duplicates), log row p16 belongs to account P16, and none / None count as NONE. Spaces are NOT ignored: 'Static ' with a trailing space is INVALID.

Sheet Accounts
A1: Account ID | B1: Preset | C1: Preset status | D1: Type override | E1: Start override | F1: DD $ override | G1: Lock offset override | H1: Touch = breach override | I1: DLL $ override | J1: Max contracts override | K1: Equity now (incl. open P&L) | L1: Day reference balance | M1: Risk $ / trade | N1: Stop ticks | O1: Tick value $ | P1: Type | Q1: Start | R1: Max DD $ | S1: Lock offset | T1: Touch = breach | U1: DLL $ | V1: Max contracts | W1: Check | X1: Peak | Y1: FLOOR | Z1: Locked | AA1: Breached | AB1: DD room | AC1: Daily room | AD1: BINDING ROOM | AE1: Binding | AF1: Effective risk | AG1: CONTRACTS | AH1: Capped | AI1: Room-limited | AJ1: floor raw | AK1: sizing check | AL1: contracts raw | AM1: Actual risk | AN1: Flags
C2: =IFERROR(INDEX(Presets!$B$2:$B$200,MATCH($B2,Presets!$A$2:$A$200,0))&"","") | P2: =IFERROR(IF(D2<>"",D2,IFERROR(INDEX(Presets!$C$2:$C$200,MATCH($B2,Presets!$A$2:$A$200,0))&"","")),"INVALID") | Q2: =IFERROR(IF(E2<>"",E2,IF(IFERROR(INDEX(Presets!$D$2:$D$200,MATCH($B2,Presets!$A$2:$A$200,0))&"","")<>"",VALUE(IFERROR(INDEX(Presets!$D$2:$D$200,MATCH($B2,Presets!$A$2:$A$200,0))&"","")),"")),"INVALID") | R2: =IFERROR(IF(F2<>"",F2,IF(IFERROR(INDEX(Presets!$E$2:$E$200,MATCH($B2,Presets!$A$2:$A$200,0))&"","")<>"",VALUE(IFERROR(INDEX(Presets!$E$2:$E$200,MATCH($B2,Presets!$A$2:$A$200,0))&"","")),IF(AND(IFERROR(INDEX(Presets!$F$2:$F$200,MATCH($B2,Presets!$A$2:$A$200,0))&"","")<>"",ISNUMBER(Q2)),VALUE(IFERROR(INDEX(Presets!$F$2:$F$200,MATCH($B2,Presets!$A$2:$A$200,0))&"",""))/100*Q2,""))),"INVALID") | S2: =IFERROR(IF(G2<>"",G2,IF(IFERROR(INDEX(Presets!$G$2:$G$200,MATCH($B2,Presets!$A$2:$A$200,0))&"","")="NONE","NONE",IF(IFERROR(INDEX(Presets!$G$2:$G$200,MATCH($B2,Presets!$A$2:$A$200,0))&"","")<>"",VALUE(IFERROR(INDEX(Presets!$G$2:$G$200,MATCH($B2,Presets!$A$2:$A$200,0))&"","")),""))),"INVALID") | T2: =IFERROR(IF(H2<>"",H2,IF(IFERROR(INDEX(Presets!$H$2:$H$200,MATCH($B2,Presets!$A$2:$A$200,0))&"","")="TRUE",TRUE,IF(IFERROR(INDEX(Presets!$H$2:$H$200,MATCH($B2,Presets!$A$2:$A$200,0))&"","")="FALSE",FALSE,""))),"INVALID") | U2: =IFERROR(IF(I2<>"",I2,IF(IFERROR(INDEX(Presets!$I$2:$I$200,MATCH($B2,Presets!$A$2:$A$200,0))&"","")="NONE","NONE",IF(IFERROR(INDEX(Presets!$I$2:$I$200,MATCH($B2,Presets!$A$2:$A$200,0))&"","")<>"",VALUE(IFERROR(INDEX(Presets!$I$2:$I$200,MATCH($B2,Presets!$A$2:$A$200,0))&"","")),""))),"INVALID") | V2: =IFERROR(IF(J2<>"",J2,IF(IFERROR(INDEX(Presets!$J$2:$J$200,MATCH($B2,Presets!$A$2:$A$200,0))&"","")<>"",VALUE(IFERROR(INDEX(Presets!$J$2:$J$200,MATCH($B2,Presets!$A$2:$A$200,0))&"","")),"")),"INVALID") | W2: =IFERROR(IF(AND(A2="",B2=""),"",IF(OR(A2="",B2="",P2="",Q2="",R2="",S2="",T2="",U2="",V2="",K2="",AND(U2<>"NONE",L2="")),"INCOMPLETE",IF(OR(COUNTIFS($A$2:$A$11,A2)>1,AND(P2<>"static",P2<>"eod_trailing",P2<>"intraday_trailing"),NOT(ISNUMBER(Q2)),Q2<=0,ROUND(Q2*100,6)<>INT(ROUND(Q2*100,6)),NOT(ISNUMBER(R2)),R2<=0,ROUND(R2*100,6)<>INT(ROUND(R2*100,6)),AND(S2<>"NONE",NOT(ISNUMBER(S2))),AND(P2="static",S2<>"NONE"),IF(ISNUMBER(S2),ROUND(Q2+S2-(Q2-R2),6)<=0,FALSE),IF(ISNUMBER(S2),OR(S2<-100000000,S2>100000000),FALSE),AND(T2<>TRUE,T2<>FALSE),AND(U2<>"NONE",OR(NOT(ISNUMBER(U2)),U2<=0)),IF(V2="NONE",FALSE,IF(ISNUMBER(V2),OR(V2<0,V2<>INT(V2)),TRUE)),NOT(ISNUMBER(K2)),AND(U2<>"NONE",NOT(ISNUMBER(L2))),Q2>100000000,R2>100000000,K2<=0,K2>100000000,IF(ISNUMBER(U2),U2>100000000,FALSE),IF(ISNUMBER(L2),OR(L2<=0,L2>100000000),FALSE)),"INVALID",IF(COUNTIFS('Daily Log'!$A$2:$A$1001,A2,'Daily Log'!$I$2:$I$1001,"INVALID")>0,"INVALID",IF(OR(COUNTIFS('Daily Log'!$A$2:$A$1001,A2,'Daily Log'!$I$2:$I$1001,"INCOMPLETE")>0,COUNTIFS('Daily Log'!$I$2:$I$1001,"UNKNOWN_ACCOUNT")>0),"INCOMPLETE","OK"))))),"INVALID") | X2: =IFERROR(IF($W2<>"OK",$W2,IF(P2="static",Q2,IF(P2="eod_trailing",MAX(Q2,_xlfn.MAXIFS('Daily Log'!$C$2:$C$1001,'Daily Log'!$A$2:$A$1001,A2)),MAX(Q2,K2,_xlfn.MAXIFS('Daily Log'!$C$2:$C$1001,'Daily Log'!$A$2:$A$1001,A2),_xlfn.MAXIFS('Daily Log'!$D$2:$D$1001,'Daily Log'!$A$2:$A$1001,A2))))),"INVALID") | Y2: =IFERROR(IF($W2<>"OK",$W2,-INT(ROUND(-(AJ2)*100,6))/100),"INVALID") | Z2: =IFERROR(IF($W2<>"OK",$W2,AND(ISNUMBER(S2),P2<>"static",ROUND(X2-R2-(Q2+IF(ISNUMBER(S2),S2,0)),6)>=0)),"INVALID") | AA2: =IFERROR(IF($W2<>"OK",$W2,OR(COUNTIFS('Daily Log'!$A$2:$A$1001,A2,'Daily Log'!$I$2:$I$1001,"BREACHED")>0,IF(T2,ROUND(K2-(AJ2),6)<=0,ROUND(K2-(AJ2),6)<0))),"INVALID") | AB2: =IFERROR(IF($W2<>"OK",$W2,IF(AA2,"BREACHED",INT(ROUND((MAX(0,K2-AJ2))*100,6))/100)),"INVALID") | AC2: =IFERROR(IF($W2<>"OK",$W2,IF(AA2,"BREACHED",IF(U2="NONE","NONE",INT(ROUND((MAX(0,U2-MAX(0,-(K2-L2))))*100,6))/100))),"INVALID") | AD2: =IFERROR(IF($W2<>"OK",$W2,IF(AA2,"BREACHED",IF(AC2="NONE",AB2,MIN(AB2,AC2)))),"INVALID") | AE2: =IFERROR(IF($W2<>"OK",$W2,IF(AA2,"BREACHED",IF(AND(AC2<>"NONE",AC2<AB2),"daily_loss","drawdown"))),"INVALID") | AF2: =IFERROR(IF(AK2<>"OK",AK2,IF(AA2,"BREACHED",INT(ROUND((MIN(M2,AD2))*100,6))/100)),"INVALID") | AG2: =IFERROR(IF(AK2<>"OK",AK2,IF(AA2,"BREACHED",IF(V2="NONE",AL2,MIN(AL2,V2)))),"INVALID") | AH2: =IFERROR(IF(AK2<>"OK",AK2,AND(V2<>"NONE",AL2>V2)),"INVALID") | AI2: =IFERROR(IF(AK2<>"OK",AK2,M2>AD2),"INVALID") | AJ2: =IFERROR(IF($W2<>"OK","",IF(P2="static",Q2-R2,IF(S2="NONE",X2-R2,MIN(X2-R2,Q2+S2)))),"INVALID") | AK2: =IFERROR(IF($W2<>"OK",$W2,IF(OR(M2="",N2="",O2=""),"INCOMPLETE",IF(OR(NOT(ISNUMBER(M2)),M2<0,NOT(ISNUMBER(N2)),N2<1,N2<>INT(N2),NOT(ISNUMBER(O2)),O2<=0,O2>100000,ROUND(O2*1000000,3)<>INT(ROUND(O2*1000000,3)),M2>100000000),"INVALID","OK"))),"INVALID") | AL2: =IFERROR(IF(AK2<>"OK","",IF(AA2,0,INT(ROUND(MIN(M2,AD2)/(N2*O2),9)))),"INVALID") | AM2: =IFERROR(IF(AK2<>"OK",AK2,IF(AA2,"BREACHED",INT(ROUND((AG2*N2*O2)*100,6))/100)),"INVALID") | AN2: =IFERROR(IF(AND(A2="",B2=""),"",_xlfn.TEXTJOIN("; ",TRUE,IF(C2="partial","PARTIAL PRESET: verify "&IFERROR(INDEX(Presets!$L$2:$L$200,MATCH($B2,Presets!$A$2:$A$200,0))&"",""),""),IF(C2="manual","MANUAL: all params user-entered",""),IF(OR(AND(D2<>"",IFERROR(INDEX(Presets!$C$2:$C$200,MATCH($B2,Presets!$A$2:$A$200,0))&"","")<>""),AND(E2<>"",IFERROR(INDEX(Presets!$D$2:$D$200,MATCH($B2,Presets!$A$2:$A$200,0))&"","")<>""),AND(F2<>"",IFERROR(INDEX(Presets!$E$2:$E$200,MATCH($B2,Presets!$A$2:$A$200,0))&"","")<>""),AND(G2<>"",IFERROR(INDEX(Presets!$G$2:$G$200,MATCH($B2,Presets!$A$2:$A$200,0))&"","")<>""),AND(H2<>"",IFERROR(INDEX(Presets!$H$2:$H$200,MATCH($B2,Presets!$A$2:$A$200,0))&"","")<>""),AND(I2<>"",IFERROR(INDEX(Presets!$I$2:$I$200,MATCH($B2,Presets!$A$2:$A$200,0))&"","")<>""),AND(J2<>"",IFERROR(INDEX(Presets!$J$2:$J$200,MATCH($B2,Presets!$A$2:$A$200,0))&"","")<>"")),"OVERRIDES PRESET",""),IF(AND(A2<>"",V2=""),"MAX CONTRACTS MISSING: enter a number or NONE",""),IF(AND(IFERROR(INDEX(Presets!$N$2:$N$200,MATCH($B2,Presets!$A$2:$A$200,0))&"","")<>"",NOT(ISNUMBER($B$13))),"AS-OF DATE MISSING: enter today in B13 (stale check off)",""),IF(AND(IFERROR(INDEX(Presets!$N$2:$N$200,MATCH($B2,Presets!$A$2:$A$200,0))&"","")<>"",ISNUMBER($B$13)),IF($B$13-DATE(VALUE(LEFT(IFERROR(INDEX(Presets!$N$2:$N$200,MATCH($B2,Presets!$A$2:$A$200,0))&"",""),4)),VALUE(MID(IFERROR(INDEX(Presets!$N$2:$N$200,MATCH($B2,Presets!$A$2:$A$200,0))&"",""),6,2)),VALUE(MID(IFERROR(INDEX(Presets!$N$2:$N$200,MATCH($B2,Presets!$A$2:$A$200,0))&"",""),9,2)))>30,"STALE PRESET: checked "&IFERROR(INDEX(Presets!$N$2:$N$200,MATCH($B2,Presets!$A$2:$A$200,0))&"","")&", over 30 days before As of",""),""),IF(IFERROR(INDEX(Presets!$M$2:$M$200,MATCH($B2,Presets!$A$2:$A$200,0))&"","")<>"","source: "&IFERROR(INDEX(Presets!$M$2:$M$200,MATCH($B2,Presets!$A$2:$A$200,0))&"","")&" checked "&IFERROR(INDEX(Presets!$N$2:$N$200,MATCH($B2,Presets!$A$2:$A$200,0))&"",""),""))),"INVALID")
C3: =IFERROR(INDEX(Presets!$B$2:$B$200,MATCH($B3,Presets!$A$2:$A$200,0))&"","") | P3: =IFERROR(IF(D3<>"",D3,IFERROR(INDEX(Presets!$C$2:$C$200,MATCH($B3,Presets!$A$2:$A$200,0))&"","")),"INVALID") | Q3: =IFERROR(IF(E3<>"",E3,IF(IFERROR(INDEX(Presets!$D$2:$D$200,MATCH($B3,Presets!$A$2:$A$200,0))&"","")<>"",VALUE(IFERROR(INDEX(Presets!$D$2:$D$200,MATCH($B3,Presets!$A$2:$A$200,0))&"","")),"")),"INVALID") | R3: =IFERROR(IF(F3<>"",F3,IF(IFERROR(INDEX(Presets!$E$2:$E$200,MATCH($B3,Presets!$A$2:$A$200,0))&"","")<>"",VALUE(IFERROR(INDEX(Presets!$E$2:$E$200,MATCH($B3,Presets!$A$2:$A$200,0))&"","")),IF(AND(IFERROR(INDEX(Presets!$F$2:$F$200,MATCH($B3,Presets!$A$2:$A$200,0))&"","")<>"",ISNUMBER(Q3)),VALUE(IFERROR(INDEX(Presets!$F$2:$F$200,MATCH($B3,Presets!$A$2:$A$200,0))&"",""))/100*Q3,""))),"INVALID") | S3: =IFERROR(IF(G3<>"",G3,IF(IFERROR(INDEX(Presets!$G$2:$G$200,MATCH($B3,Presets!$A$2:$A$200,0))&"","")="NONE","NONE",IF(IFERROR(INDEX(Presets!$G$2:$G$200,MATCH($B3,Presets!$A$2:$A$200,0))&"","")<>"",VALUE(IFERROR(INDEX(Presets!$G$2:$G$200,MATCH($B3,Presets!$A$2:$A$200,0))&"","")),""))),"INVALID") | T3: =IFERROR(IF(H3<>"",H3,IF(IFERROR(INDEX(Presets!$H$2:$H$200,MATCH($B3,Presets!$A$2:$A$200,0))&"","")="TRUE",TRUE,IF(IFERROR(INDEX(Presets!$H$2:$H$200,MATCH($B3,Presets!$A$2:$A$200,0))&"","")="FALSE",FALSE,""))),"INVALID") | U3: =IFERROR(IF(I3<>"",I3,IF(IFERROR(INDEX(Presets!$I$2:$I$200,MATCH($B3,Presets!$A$2:$A$200,0))&"","")="NONE","NONE",IF(IFERROR(INDEX(Presets!$I$2:$I$200,MATCH($B3,Presets!$A$2:$A$200,0))&"","")<>"",VALUE(IFERROR(INDEX(Presets!$I$2:$I$200,MATCH($B3,Presets!$A$2:$A$200,0))&"","")),""))),"INVALID") | V3: =IFERROR(IF(J3<>"",J3,IF(IFERROR(INDEX(Presets!$J$2:$J$200,MATCH($B3,Presets!$A$2:$A$200,0))&"","")<>"",VALUE(IFERROR(INDEX(Presets!$J$2:$J$200,MATCH($B3,Presets!$A$2:$A$200,0))&"","")),"")),"INVALID") | W3: =IFERROR(IF(AND(A3="",B3=""),"",IF(OR(A3="",B3="",P3="",Q3="",R3="",S3="",T3="",U3="",V3="",K3="",AND(U3<>"NONE",L3="")),"INCOMPLETE",IF(OR(COUNTIFS($A$2:$A$11,A3)>1,AND(P3<>"static",P3<>"eod_trailing",P3<>"intraday_trailing"),NOT(ISNUMBER(Q3)),Q3<=0,ROUND(Q3*100,6)<>INT(ROUND(Q3*100,6)),NOT(ISNUMBER(R3)),R3<=0,ROUND(R3*100,6)<>INT(ROUND(R3*100,6)),AND(S3<>"NONE",NOT(ISNUMBER(S3))),AND(P3="static",S3<>"NONE"),IF(ISNUMBER(S3),ROUND(Q3+S3-(Q3-R3),6)<=0,FALSE),IF(ISNUMBER(S3),OR(S3<-100000000,S3>100000000),FALSE),AND(T3<>TRUE,T3<>FALSE),AND(U3<>"NONE",OR(NOT(ISNUMBER(U3)),U3<=0)),IF(V3="NONE",FALSE,IF(ISNUMBER(V3),OR(V3<0,V3<>INT(V3)),TRUE)),NOT(ISNUMBER(K3)),AND(U3<>"NONE",NOT(ISNUMBER(L3))),Q3>100000000,R3>100000000,K3<=0,K3>100000000,IF(ISNUMBER(U3),U3>100000000,FALSE),IF(ISNUMBER(L3),OR(L3<=0,L3>100000000),FALSE)),"INVALID",IF(COUNTIFS('Daily Log'!$A$2:$A$1001,A3,'Daily Log'!$I$2:$I$1001,"INVALID")>0,"INVALID",IF(OR(COUNTIFS('Daily Log'!$A$2:$A$1001,A3,'Daily Log'!$I$2:$I$1001,"INCOMPLETE")>0,COUNTIFS('Daily Log'!$I$2:$I$1001,"UNKNOWN_ACCOUNT")>0),"INCOMPLETE","OK"))))),"INVALID") | X3: =IFERROR(IF($W3<>"OK",$W3,IF(P3="static",Q3,IF(P3="eod_trailing",MAX(Q3,_xlfn.MAXIFS('Daily Log'!$C$2:$C$1001,'Daily Log'!$A$2:$A$1001,A3)),MAX(Q3,K3,_xlfn.MAXIFS('Daily Log'!$C$2:$C$1001,'Daily Log'!$A$2:$A$1001,A3),_xlfn.MAXIFS('Daily Log'!$D$2:$D$1001,'Daily Log'!$A$2:$A$1001,A3))))),"INVALID") | Y3: =IFERROR(IF($W3<>"OK",$W3,-INT(ROUND(-(AJ3)*100,6))/100),"INVALID") | Z3: =IFERROR(IF($W3<>"OK",$W3,AND(ISNUMBER(S3),P3<>"static",ROUND(X3-R3-(Q3+IF(ISNUMBER(S3),S3,0)),6)>=0)),"INVALID") | AA3: =IFERROR(IF($W3<>"OK",$W3,OR(COUNTIFS('Daily Log'!$A$2:$A$1001,A3,'Daily Log'!$I$2:$I$1001,"BREACHED")>0,IF(T3,ROUND(K3-(AJ3),6)<=0,ROUND(K3-(AJ3),6)<0))),"INVALID") | AB3: =IFERROR(IF($W3<>"OK",$W3,IF(AA3,"BREACHED",INT(ROUND((MAX(0,K3-AJ3))*100,6))/100)),"INVALID") | AC3: =IFERROR(IF($W3<>"OK",$W3,IF(AA3,"BREACHED",IF(U3="NONE","NONE",INT(ROUND((MAX(0,U3-MAX(0,-(K3-L3))))*100,6))/100))),"INVALID") | AD3: =IFERROR(IF($W3<>"OK",$W3,IF(AA3,"BREACHED",IF(AC3="NONE",AB3,MIN(AB3,AC3)))),"INVALID") | AE3: =IFERROR(IF($W3<>"OK",$W3,IF(AA3,"BREACHED",IF(AND(AC3<>"NONE",AC3<AB3),"daily_loss","drawdown"))),"INVALID") | AF3: =IFERROR(IF(AK3<>"OK",AK3,IF(AA3,"BREACHED",INT(ROUND((MIN(M3,AD3))*100,6))/100)),"INVALID") | AG3: =IFERROR(IF(AK3<>"OK",AK3,IF(AA3,"BREACHED",IF(V3="NONE",AL3,MIN(AL3,V3)))),"INVALID") | AH3: =IFERROR(IF(AK3<>"OK",AK3,AND(V3<>"NONE",AL3>V3)),"INVALID") | AI3: =IFERROR(IF(AK3<>"OK",AK3,M3>AD3),"INVALID") | AJ3: =IFERROR(IF($W3<>"OK","",IF(P3="static",Q3-R3,IF(S3="NONE",X3-R3,MIN(X3-R3,Q3+S3)))),"INVALID") | AK3: =IFERROR(IF($W3<>"OK",$W3,IF(OR(M3="",N3="",O3=""),"INCOMPLETE",IF(OR(NOT(ISNUMBER(M3)),M3<0,NOT(ISNUMBER(N3)),N3<1,N3<>INT(N3),NOT(ISNUMBER(O3)),O3<=0,O3>100000,ROUND(O3*1000000,3)<>INT(ROUND(O3*1000000,3)),M3>100000000),"INVALID","OK"))),"INVALID") | AL3: =IFERROR(IF(AK3<>"OK","",IF(AA3,0,INT(ROUND(MIN(M3,AD3)/(N3*O3),9)))),"INVALID") | AM3: =IFERROR(IF(AK3<>"OK",AK3,IF(AA3,"BREACHED",INT(ROUND((AG3*N3*O3)*100,6))/100)),"INVALID") | AN3: =IFERROR(IF(AND(A3="",B3=""),"",_xlfn.TEXTJOIN("; ",TRUE,IF(C3="partial","PARTIAL PRESET: verify "&IFERROR(INDEX(Presets!$L$2:$L$200,MATCH($B3,Presets!$A$2:$A$200,0))&"",""),""),IF(C3="manual","MANUAL: all params user-entered",""),IF(OR(AND(D3<>"",IFERROR(INDEX(Presets!$C$2:$C$200,MATCH($B3,Presets!$A$2:$A$200,0))&"","")<>""),AND(E3<>"",IFERROR(INDEX(Presets!$D$2:$D$200,MATCH($B3,Presets!$A$2:$A$200,0))&"","")<>""),AND(F3<>"",IFERROR(INDEX(Presets!$E$2:$E$200,MATCH($B3,Presets!$A$2:$A$200,0))&"","")<>""),AND(G3<>"",IFERROR(INDEX(Presets!$G$2:$G$200,MATCH($B3,Presets!$A$2:$A$200,0))&"","")<>""),AND(H3<>"",IFERROR(INDEX(Presets!$H$2:$H$200,MATCH($B3,Presets!$A$2:$A$200,0))&"","")<>""),AND(I3<>"",IFERROR(INDEX(Presets!$I$2:$I$200,MATCH($B3,Presets!$A$2:$A$200,0))&"","")<>""),AND(J3<>"",IFERROR(INDEX(Presets!$J$2:$J$200,MATCH($B3,Presets!$A$2:$A$200,0))&"","")<>"")),"OVERRIDES PRESET",""),IF(AND(A3<>"",V3=""),"MAX CONTRACTS MISSING: enter a number or NONE",""),IF(AND(IFERROR(INDEX(Presets!$N$2:$N$200,MATCH($B3,Presets!$A$2:$A$200,0))&"","")<>"",NOT(ISNUMBER($B$13))),"AS-OF DATE MISSING: enter today in B13 (stale check off)",""),IF(AND(IFERROR(INDEX(Presets!$N$2:$N$200,MATCH($B3,Presets!$A$2:$A$200,0))&"","")<>"",ISNUMBER($B$13)),IF($B$13-DATE(VALUE(LEFT(IFERROR(INDEX(Presets!$N$2:$N$200,MATCH($B3,Presets!$A$2:$A$200,0))&"",""),4)),VALUE(MID(IFERROR(INDEX(Presets!$N$2:$N$200,MATCH($B3,Presets!$A$2:$A$200,0))&"",""),6,2)),VALUE(MID(IFERROR(INDEX(Presets!$N$2:$N$200,MATCH($B3,Presets!$A$2:$A$200,0))&"",""),9,2)))>30,"STALE PRESET: checked "&IFERROR(INDEX(Presets!$N$2:$N$200,MATCH($B3,Presets!$A$2:$A$200,0))&"","")&", over 30 days before As of",""),""),IF(IFERROR(INDEX(Presets!$M$2:$M$200,MATCH($B3,Presets!$A$2:$A$200,0))&"","")<>"","source: "&IFERROR(INDEX(Presets!$M$2:$M$200,MATCH($B3,Presets!$A$2:$A$200,0))&"","")&" checked "&IFERROR(INDEX(Presets!$N$2:$N$200,MATCH($B3,Presets!$A$2:$A$200,0))&"",""),""))),"INVALID")
C4: =IFERROR(INDEX(Presets!$B$2:$B$200,MATCH($B4,Presets!$A$2:$A$200,0))&"","") | P4: =IFERROR(IF(D4<>"",D4,IFERROR(INDEX(Presets!$C$2:$C$200,MATCH($B4,Presets!$A$2:$A$200,0))&"","")),"INVALID") | Q4: =IFERROR(IF(E4<>"",E4,IF(IFERROR(INDEX(Presets!$D$2:$D$200,MATCH($B4,Presets!$A$2:$A$200,0))&"","")<>"",VALUE(IFERROR(INDEX(Presets!$D$2:$D$200,MATCH($B4,Presets!$A$2:$A$200,0))&"","")),"")),"INVALID") | R4: =IFERROR(IF(F4<>"",F4,IF(IFERROR(INDEX(Presets!$E$2:$E$200,MATCH($B4,Presets!$A$2:$A$200,0))&"","")<>"",VALUE(IFERROR(INDEX(Presets!$E$2:$E$200,MATCH($B4,Presets!$A$2:$A$200,0))&"","")),IF(AND(IFERROR(INDEX(Presets!$F$2:$F$200,MATCH($B4,Presets!$A$2:$A$200,0))&"","")<>"",ISNUMBER(Q4)),VALUE(IFERROR(INDEX(Presets!$F$2:$F$200,MATCH($B4,Presets!$A$2:$A$200,0))&"",""))/100*Q4,""))),"INVALID") | S4: =IFERROR(IF(G4<>"",G4,IF(IFERROR(INDEX(Presets!$G$2:$G$200,MATCH($B4,Presets!$A$2:$A$200,0))&"","")="NONE","NONE",IF(IFERROR(INDEX(Presets!$G$2:$G$200,MATCH($B4,Presets!$A$2:$A$200,0))&"","")<>"",VALUE(IFERROR(INDEX(Presets!$G$2:$G$200,MATCH($B4,Presets!$A$2:$A$200,0))&"","")),""))),"INVALID") | T4: =IFERROR(IF(H4<>"",H4,IF(IFERROR(INDEX(Presets!$H$2:$H$200,MATCH($B4,Presets!$A$2:$A$200,0))&"","")="TRUE",TRUE,IF(IFERROR(INDEX(Presets!$H$2:$H$200,MATCH($B4,Presets!$A$2:$A$200,0))&"","")="FALSE",FALSE,""))),"INVALID") | U4: =IFERROR(IF(I4<>"",I4,IF(IFERROR(INDEX(Presets!$I$2:$I$200,MATCH($B4,Presets!$A$2:$A$200,0))&"","")="NONE","NONE",IF(IFERROR(INDEX(Presets!$I$2:$I$200,MATCH($B4,Presets!$A$2:$A$200,0))&"","")<>"",VALUE(IFERROR(INDEX(Presets!$I$2:$I$200,MATCH($B4,Presets!$A$2:$A$200,0))&"","")),""))),"INVALID") | V4: =IFERROR(IF(J4<>"",J4,IF(IFERROR(INDEX(Presets!$J$2:$J$200,MATCH($B4,Presets!$A$2:$A$200,0))&"","")<>"",VALUE(IFERROR(INDEX(Presets!$J$2:$J$200,MATCH($B4,Presets!$A$2:$A$200,0))&"","")),"")),"INVALID") | W4: =IFERROR(IF(AND(A4="",B4=""),"",IF(OR(A4="",B4="",P4="",Q4="",R4="",S4="",T4="",U4="",V4="",K4="",AND(U4<>"NONE",L4="")),"INCOMPLETE",IF(OR(COUNTIFS($A$2:$A$11,A4)>1,AND(P4<>"static",P4<>"eod_trailing",P4<>"intraday_trailing"),NOT(ISNUMBER(Q4)),Q4<=0,ROUND(Q4*100,6)<>INT(ROUND(Q4*100,6)),NOT(ISNUMBER(R4)),R4<=0,ROUND(R4*100,6)<>INT(ROUND(R4*100,6)),AND(S4<>"NONE",NOT(ISNUMBER(S4))),AND(P4="static",S4<>"NONE"),IF(ISNUMBER(S4),ROUND(Q4+S4-(Q4-R4),6)<=0,FALSE),IF(ISNUMBER(S4),OR(S4<-100000000,S4>100000000),FALSE),AND(T4<>TRUE,T4<>FALSE),AND(U4<>"NONE",OR(NOT(ISNUMBER(U4)),U4<=0)),IF(V4="NONE",FALSE,IF(ISNUMBER(V4),OR(V4<0,V4<>INT(V4)),TRUE)),NOT(ISNUMBER(K4)),AND(U4<>"NONE",NOT(ISNUMBER(L4))),Q4>100000000,R4>100000000,K4<=0,K4>100000000,IF(ISNUMBER(U4),U4>100000000,FALSE),IF(ISNUMBER(L4),OR(L4<=0,L4>100000000),FALSE)),"INVALID",IF(COUNTIFS('Daily Log'!$A$2:$A$1001,A4,'Daily Log'!$I$2:$I$1001,"INVALID")>0,"INVALID",IF(OR(COUNTIFS('Daily Log'!$A$2:$A$1001,A4,'Daily Log'!$I$2:$I$1001,"INCOMPLETE")>0,COUNTIFS('Daily Log'!$I$2:$I$1001,"UNKNOWN_ACCOUNT")>0),"INCOMPLETE","OK"))))),"INVALID") | X4: =IFERROR(IF($W4<>"OK",$W4,IF(P4="static",Q4,IF(P4="eod_trailing",MAX(Q4,_xlfn.MAXIFS('Daily Log'!$C$2:$C$1001,'Daily Log'!$A$2:$A$1001,A4)),MAX(Q4,K4,_xlfn.MAXIFS('Daily Log'!$C$2:$C$1001,'Daily Log'!$A$2:$A$1001,A4),_xlfn.MAXIFS('Daily Log'!$D$2:$D$1001,'Daily Log'!$A$2:$A$1001,A4))))),"INVALID") | Y4: =IFERROR(IF($W4<>"OK",$W4,-INT(ROUND(-(AJ4)*100,6))/100),"INVALID") | Z4: =IFERROR(IF($W4<>"OK",$W4,AND(ISNUMBER(S4),P4<>"static",ROUND(X4-R4-(Q4+IF(ISNUMBER(S4),S4,0)),6)>=0)),"INVALID") | AA4: =IFERROR(IF($W4<>"OK",$W4,OR(COUNTIFS('Daily Log'!$A$2:$A$1001,A4,'Daily Log'!$I$2:$I$1001,"BREACHED")>0,IF(T4,ROUND(K4-(AJ4),6)<=0,ROUND(K4-(AJ4),6)<0))),"INVALID") | AB4: =IFERROR(IF($W4<>"OK",$W4,IF(AA4,"BREACHED",INT(ROUND((MAX(0,K4-AJ4))*100,6))/100)),"INVALID") | AC4: =IFERROR(IF($W4<>"OK",$W4,IF(AA4,"BREACHED",IF(U4="NONE","NONE",INT(ROUND((MAX(0,U4-MAX(0,-(K4-L4))))*100,6))/100))),"INVALID") | AD4: =IFERROR(IF($W4<>"OK",$W4,IF(AA4,"BREACHED",IF(AC4="NONE",AB4,MIN(AB4,AC4)))),"INVALID") | AE4: =IFERROR(IF($W4<>"OK",$W4,IF(AA4,"BREACHED",IF(AND(AC4<>"NONE",AC4<AB4),"daily_loss","drawdown"))),"INVALID") | AF4: =IFERROR(IF(AK4<>"OK",AK4,IF(AA4,"BREACHED",INT(ROUND((MIN(M4,AD4))*100,6))/100)),"INVALID") | AG4: =IFERROR(IF(AK4<>"OK",AK4,IF(AA4,"BREACHED",IF(V4="NONE",AL4,MIN(AL4,V4)))),"INVALID") | AH4: =IFERROR(IF(AK4<>"OK",AK4,AND(V4<>"NONE",AL4>V4)),"INVALID") | AI4: =IFERROR(IF(AK4<>"OK",AK4,M4>AD4),"INVALID") | AJ4: =IFERROR(IF($W4<>"OK","",IF(P4="static",Q4-R4,IF(S4="NONE",X4-R4,MIN(X4-R4,Q4+S4)))),"INVALID") | AK4: =IFERROR(IF($W4<>"OK",$W4,IF(OR(M4="",N4="",O4=""),"INCOMPLETE",IF(OR(NOT(ISNUMBER(M4)),M4<0,NOT(ISNUMBER(N4)),N4<1,N4<>INT(N4),NOT(ISNUMBER(O4)),O4<=0,O4>100000,ROUND(O4*1000000,3)<>INT(ROUND(O4*1000000,3)),M4>100000000),"INVALID","OK"))),"INVALID") | AL4: =IFERROR(IF(AK4<>"OK","",IF(AA4,0,INT(ROUND(MIN(M4,AD4)/(N4*O4),9)))),"INVALID") | AM4: =IFERROR(IF(AK4<>"OK",AK4,IF(AA4,"BREACHED",INT(ROUND((AG4*N4*O4)*100,6))/100)),"INVALID") | AN4: =IFERROR(IF(AND(A4="",B4=""),"",_xlfn.TEXTJOIN("; ",TRUE,IF(C4="partial","PARTIAL PRESET: verify "&IFERROR(INDEX(Presets!$L$2:$L$200,MATCH($B4,Presets!$A$2:$A$200,0))&"",""),""),IF(C4="manual","MANUAL: all params user-entered",""),IF(OR(AND(D4<>"",IFERROR(INDEX(Presets!$C$2:$C$200,MATCH($B4,Presets!$A$2:$A$200,0))&"","")<>""),AND(E4<>"",IFERROR(INDEX(Presets!$D$2:$D$200,MATCH($B4,Presets!$A$2:$A$200,0))&"","")<>""),AND(F4<>"",IFERROR(INDEX(Presets!$E$2:$E$200,MATCH($B4,Presets!$A$2:$A$200,0))&"","")<>""),AND(G4<>"",IFERROR(INDEX(Presets!$G$2:$G$200,MATCH($B4,Presets!$A$2:$A$200,0))&"","")<>""),AND(H4<>"",IFERROR(INDEX(Presets!$H$2:$H$200,MATCH($B4,Presets!$A$2:$A$200,0))&"","")<>""),AND(I4<>"",IFERROR(INDEX(Presets!$I$2:$I$200,MATCH($B4,Presets!$A$2:$A$200,0))&"","")<>""),AND(J4<>"",IFERROR(INDEX(Presets!$J$2:$J$200,MATCH($B4,Presets!$A$2:$A$200,0))&"","")<>"")),"OVERRIDES PRESET",""),IF(AND(A4<>"",V4=""),"MAX CONTRACTS MISSING: enter a number or NONE",""),IF(AND(IFERROR(INDEX(Presets!$N$2:$N$200,MATCH($B4,Presets!$A$2:$A$200,0))&"","")<>"",NOT(ISNUMBER($B$13))),"AS-OF DATE MISSING: enter today in B13 (stale check off)",""),IF(AND(IFERROR(INDEX(Presets!$N$2:$N$200,MATCH($B4,Presets!$A$2:$A$200,0))&"","")<>"",ISNUMBER($B$13)),IF($B$13-DATE(VALUE(LEFT(IFERROR(INDEX(Presets!$N$2:$N$200,MATCH($B4,Presets!$A$2:$A$200,0))&"",""),4)),VALUE(MID(IFERROR(INDEX(Presets!$N$2:$N$200,MATCH($B4,Presets!$A$2:$A$200,0))&"",""),6,2)),VALUE(MID(IFERROR(INDEX(Presets!$N$2:$N$200,MATCH($B4,Presets!$A$2:$A$200,0))&"",""),9,2)))>30,"STALE PRESET: checked "&IFERROR(INDEX(Presets!$N$2:$N$200,MATCH($B4,Presets!$A$2:$A$200,0))&"","")&", over 30 days before As of",""),""),IF(IFERROR(INDEX(Presets!$M$2:$M$200,MATCH($B4,Presets!$A$2:$A$200,0))&"","")<>"","source: "&IFERROR(INDEX(Presets!$M$2:$M$200,MATCH($B4,Presets!$A$2:$A$200,0))&"","")&" checked "&IFERROR(INDEX(Presets!$N$2:$N$200,MATCH($B4,Presets!$A$2:$A$200,0))&"",""),""))),"INVALID")
C5: =IFERROR(INDEX(Presets!$B$2:$B$200,MATCH($B5,Presets!$A$2:$A$200,0))&"","") | P5: =IFERROR(IF(D5<>"",D5,IFERROR(INDEX(Presets!$C$2:$C$200,MATCH($B5,Presets!$A$2:$A$200,0))&"","")),"INVALID") | Q5: =IFERROR(IF(E5<>"",E5,IF(IFERROR(INDEX(Presets!$D$2:$D$200,MATCH($B5,Presets!$A$2:$A$200,0))&"","")<>"",VALUE(IFERROR(INDEX(Presets!$D$2:$D$200,MATCH($B5,Presets!$A$2:$A$200,0))&"","")),"")),"INVALID") | R5: =IFERROR(IF(F5<>"",F5,IF(IFERROR(INDEX(Presets!$E$2:$E$200,MATCH($B5,Presets!$A$2:$A$200,0))&"","")<>"",VALUE(IFERROR(INDEX(Presets!$E$2:$E$200,MATCH($B5,Presets!$A$2:$A$200,0))&"","")),IF(AND(IFERROR(INDEX(Presets!$F$2:$F$200,MATCH($B5,Presets!$A$2:$A$200,0))&"","")<>"",ISNUMBER(Q5)),VALUE(IFERROR(INDEX(Presets!$F$2:$F$200,MATCH($B5,Presets!$A$2:$A$200,0))&"",""))/100*Q5,""))),"INVALID") | S5: =IFERROR(IF(G5<>"",G5,IF(IFERROR(INDEX(Presets!$G$2:$G$200,MATCH($B5,Presets!$A$2:$A$200,0))&"","")="NONE","NONE",IF(IFERROR(INDEX(Presets!$G$2:$G$200,MATCH($B5,Presets!$A$2:$A$200,0))&"","")<>"",VALUE(IFERROR(INDEX(Presets!$G$2:$G$200,MATCH($B5,Presets!$A$2:$A$200,0))&"","")),""))),"INVALID") | T5: =IFERROR(IF(H5<>"",H5,IF(IFERROR(INDEX(Presets!$H$2:$H$200,MATCH($B5,Presets!$A$2:$A$200,0))&"","")="TRUE",TRUE,IF(IFERROR(INDEX(Presets!$H$2:$H$200,MATCH($B5,Presets!$A$2:$A$200,0))&"","")="FALSE",FALSE,""))),"INVALID") | U5: =IFERROR(IF(I5<>"",I5,IF(IFERROR(INDEX(Presets!$I$2:$I$200,MATCH($B5,Presets!$A$2:$A$200,0))&"","")="NONE","NONE",IF(IFERROR(INDEX(Presets!$I$2:$I$200,MATCH($B5,Presets!$A$2:$A$200,0))&"","")<>"",VALUE(IFERROR(INDEX(Presets!$I$2:$I$200,MATCH($B5,Presets!$A$2:$A$200,0))&"","")),""))),"INVALID") | V5: =IFERROR(IF(J5<>"",J5,IF(IFERROR(INDEX(Presets!$J$2:$J$200,MATCH($B5,Presets!$A$2:$A$200,0))&"","")<>"",VALUE(IFERROR(INDEX(Presets!$J$2:$J$200,MATCH($B5,Presets!$A$2:$A$200,0))&"","")),"")),"INVALID") | W5: =IFERROR(IF(AND(A5="",B5=""),"",IF(OR(A5="",B5="",P5="",Q5="",R5="",S5="",T5="",U5="",V5="",K5="",AND(U5<>"NONE",L5="")),"INCOMPLETE",IF(OR(COUNTIFS($A$2:$A$11,A5)>1,AND(P5<>"static",P5<>"eod_trailing",P5<>"intraday_trailing"),NOT(ISNUMBER(Q5)),Q5<=0,ROUND(Q5*100,6)<>INT(ROUND(Q5*100,6)),NOT(ISNUMBER(R5)),R5<=0,ROUND(R5*100,6)<>INT(ROUND(R5*100,6)),AND(S5<>"NONE",NOT(ISNUMBER(S5))),AND(P5="static",S5<>"NONE"),IF(ISNUMBER(S5),ROUND(Q5+S5-(Q5-R5),6)<=0,FALSE),IF(ISNUMBER(S5),OR(S5<-100000000,S5>100000000),FALSE),AND(T5<>TRUE,T5<>FALSE),AND(U5<>"NONE",OR(NOT(ISNUMBER(U5)),U5<=0)),IF(V5="NONE",FALSE,IF(ISNUMBER(V5),OR(V5<0,V5<>INT(V5)),TRUE)),NOT(ISNUMBER(K5)),AND(U5<>"NONE",NOT(ISNUMBER(L5))),Q5>100000000,R5>100000000,K5<=0,K5>100000000,IF(ISNUMBER(U5),U5>100000000,FALSE),IF(ISNUMBER(L5),OR(L5<=0,L5>100000000),FALSE)),"INVALID",IF(COUNTIFS('Daily Log'!$A$2:$A$1001,A5,'Daily Log'!$I$2:$I$1001,"INVALID")>0,"INVALID",IF(OR(COUNTIFS('Daily Log'!$A$2:$A$1001,A5,'Daily Log'!$I$2:$I$1001,"INCOMPLETE")>0,COUNTIFS('Daily Log'!$I$2:$I$1001,"UNKNOWN_ACCOUNT")>0),"INCOMPLETE","OK"))))),"INVALID") | X5: =IFERROR(IF($W5<>"OK",$W5,IF(P5="static",Q5,IF(P5="eod_trailing",MAX(Q5,_xlfn.MAXIFS('Daily Log'!$C$2:$C$1001,'Daily Log'!$A$2:$A$1001,A5)),MAX(Q5,K5,_xlfn.MAXIFS('Daily Log'!$C$2:$C$1001,'Daily Log'!$A$2:$A$1001,A5),_xlfn.MAXIFS('Daily Log'!$D$2:$D$1001,'Daily Log'!$A$2:$A$1001,A5))))),"INVALID") | Y5: =IFERROR(IF($W5<>"OK",$W5,-INT(ROUND(-(AJ5)*100,6))/100),"INVALID") | Z5: =IFERROR(IF($W5<>"OK",$W5,AND(ISNUMBER(S5),P5<>"static",ROUND(X5-R5-(Q5+IF(ISNUMBER(S5),S5,0)),6)>=0)),"INVALID") | AA5: =IFERROR(IF($W5<>"OK",$W5,OR(COUNTIFS('Daily Log'!$A$2:$A$1001,A5,'Daily Log'!$I$2:$I$1001,"BREACHED")>0,IF(T5,ROUND(K5-(AJ5),6)<=0,ROUND(K5-(AJ5),6)<0))),"INVALID") | AB5: =IFERROR(IF($W5<>"OK",$W5,IF(AA5,"BREACHED",INT(ROUND((MAX(0,K5-AJ5))*100,6))/100)),"INVALID") | AC5: =IFERROR(IF($W5<>"OK",$W5,IF(AA5,"BREACHED",IF(U5="NONE","NONE",INT(ROUND((MAX(0,U5-MAX(0,-(K5-L5))))*100,6))/100))),"INVALID") | AD5: =IFERROR(IF($W5<>"OK",$W5,IF(AA5,"BREACHED",IF(AC5="NONE",AB5,MIN(AB5,AC5)))),"INVALID") | AE5: =IFERROR(IF($W5<>"OK",$W5,IF(AA5,"BREACHED",IF(AND(AC5<>"NONE",AC5<AB5),"daily_loss","drawdown"))),"INVALID") | AF5: =IFERROR(IF(AK5<>"OK",AK5,IF(AA5,"BREACHED",INT(ROUND((MIN(M5,AD5))*100,6))/100)),"INVALID") | AG5: =IFERROR(IF(AK5<>"OK",AK5,IF(AA5,"BREACHED",IF(V5="NONE",AL5,MIN(AL5,V5)))),"INVALID") | AH5: =IFERROR(IF(AK5<>"OK",AK5,AND(V5<>"NONE",AL5>V5)),"INVALID") | AI5: =IFERROR(IF(AK5<>"OK",AK5,M5>AD5),"INVALID") | AJ5: =IFERROR(IF($W5<>"OK","",IF(P5="static",Q5-R5,IF(S5="NONE",X5-R5,MIN(X5-R5,Q5+S5)))),"INVALID") | AK5: =IFERROR(IF($W5<>"OK",$W5,IF(OR(M5="",N5="",O5=""),"INCOMPLETE",IF(OR(NOT(ISNUMBER(M5)),M5<0,NOT(ISNUMBER(N5)),N5<1,N5<>INT(N5),NOT(ISNUMBER(O5)),O5<=0,O5>100000,ROUND(O5*1000000,3)<>INT(ROUND(O5*1000000,3)),M5>100000000),"INVALID","OK"))),"INVALID") | AL5: =IFERROR(IF(AK5<>"OK","",IF(AA5,0,INT(ROUND(MIN(M5,AD5)/(N5*O5),9)))),"INVALID") | AM5: =IFERROR(IF(AK5<>"OK",AK5,IF(AA5,"BREACHED",INT(ROUND((AG5*N5*O5)*100,6))/100)),"INVALID") | AN5: =IFERROR(IF(AND(A5="",B5=""),"",_xlfn.TEXTJOIN("; ",TRUE,IF(C5="partial","PARTIAL PRESET: verify "&IFERROR(INDEX(Presets!$L$2:$L$200,MATCH($B5,Presets!$A$2:$A$200,0))&"",""),""),IF(C5="manual","MANUAL: all params user-entered",""),IF(OR(AND(D5<>"",IFERROR(INDEX(Presets!$C$2:$C$200,MATCH($B5,Presets!$A$2:$A$200,0))&"","")<>""),AND(E5<>"",IFERROR(INDEX(Presets!$D$2:$D$200,MATCH($B5,Presets!$A$2:$A$200,0))&"","")<>""),AND(F5<>"",IFERROR(INDEX(Presets!$E$2:$E$200,MATCH($B5,Presets!$A$2:$A$200,0))&"","")<>""),AND(G5<>"",IFERROR(INDEX(Presets!$G$2:$G$200,MATCH($B5,Presets!$A$2:$A$200,0))&"","")<>""),AND(H5<>"",IFERROR(INDEX(Presets!$H$2:$H$200,MATCH($B5,Presets!$A$2:$A$200,0))&"","")<>""),AND(I5<>"",IFERROR(INDEX(Presets!$I$2:$I$200,MATCH($B5,Presets!$A$2:$A$200,0))&"","")<>""),AND(J5<>"",IFERROR(INDEX(Presets!$J$2:$J$200,MATCH($B5,Presets!$A$2:$A$200,0))&"","")<>"")),"OVERRIDES PRESET",""),IF(AND(A5<>"",V5=""),"MAX CONTRACTS MISSING: enter a number or NONE",""),IF(AND(IFERROR(INDEX(Presets!$N$2:$N$200,MATCH($B5,Presets!$A$2:$A$200,0))&"","")<>"",NOT(ISNUMBER($B$13))),"AS-OF DATE MISSING: enter today in B13 (stale check off)",""),IF(AND(IFERROR(INDEX(Presets!$N$2:$N$200,MATCH($B5,Presets!$A$2:$A$200,0))&"","")<>"",ISNUMBER($B$13)),IF($B$13-DATE(VALUE(LEFT(IFERROR(INDEX(Presets!$N$2:$N$200,MATCH($B5,Presets!$A$2:$A$200,0))&"",""),4)),VALUE(MID(IFERROR(INDEX(Presets!$N$2:$N$200,MATCH($B5,Presets!$A$2:$A$200,0))&"",""),6,2)),VALUE(MID(IFERROR(INDEX(Presets!$N$2:$N$200,MATCH($B5,Presets!$A$2:$A$200,0))&"",""),9,2)))>30,"STALE PRESET: checked "&IFERROR(INDEX(Presets!$N$2:$N$200,MATCH($B5,Presets!$A$2:$A$200,0))&"","")&", over 30 days before As of",""),""),IF(IFERROR(INDEX(Presets!$M$2:$M$200,MATCH($B5,Presets!$A$2:$A$200,0))&"","")<>"","source: "&IFERROR(INDEX(Presets!$M$2:$M$200,MATCH($B5,Presets!$A$2:$A$200,0))&"","")&" checked "&IFERROR(INDEX(Presets!$N$2:$N$200,MATCH($B5,Presets!$A$2:$A$200,0))&"",""),""))),"INVALID")
C6: =IFERROR(INDEX(Presets!$B$2:$B$200,MATCH($B6,Presets!$A$2:$A$200,0))&"","") | P6: =IFERROR(IF(D6<>"",D6,IFERROR(INDEX(Presets!$C$2:$C$200,MATCH($B6,Presets!$A$2:$A$200,0))&"","")),"INVALID") | Q6: =IFERROR(IF(E6<>"",E6,IF(IFERROR(INDEX(Presets!$D$2:$D$200,MATCH($B6,Presets!$A$2:$A$200,0))&"","")<>"",VALUE(IFERROR(INDEX(Presets!$D$2:$D$200,MATCH($B6,Presets!$A$2:$A$200,0))&"","")),"")),"INVALID") | R6: =IFERROR(IF(F6<>"",F6,IF(IFERROR(INDEX(Presets!$E$2:$E$200,MATCH($B6,Presets!$A$2:$A$200,0))&"","")<>"",VALUE(IFERROR(INDEX(Presets!$E$2:$E$200,MATCH($B6,Presets!$A$2:$A$200,0))&"","")),IF(AND(IFERROR(INDEX(Presets!$F$2:$F$200,MATCH($B6,Presets!$A$2:$A$200,0))&"","")<>"",ISNUMBER(Q6)),VALUE(IFERROR(INDEX(Presets!$F$2:$F$200,MATCH($B6,Presets!$A$2:$A$200,0))&"",""))/100*Q6,""))),"INVALID") | S6: =IFERROR(IF(G6<>"",G6,IF(IFERROR(INDEX(Presets!$G$2:$G$200,MATCH($B6,Presets!$A$2:$A$200,0))&"","")="NONE","NONE",IF(IFERROR(INDEX(Presets!$G$2:$G$200,MATCH($B6,Presets!$A$2:$A$200,0))&"","")<>"",VALUE(IFERROR(INDEX(Presets!$G$2:$G$200,MATCH($B6,Presets!$A$2:$A$200,0))&"","")),""))),"INVALID") | T6: =IFERROR(IF(H6<>"",H6,IF(IFERROR(INDEX(Presets!$H$2:$H$200,MATCH($B6,Presets!$A$2:$A$200,0))&"","")="TRUE",TRUE,IF(IFERROR(INDEX(Presets!$H$2:$H$200,MATCH($B6,Presets!$A$2:$A$200,0))&"","")="FALSE",FALSE,""))),"INVALID") | U6: =IFERROR(IF(I6<>"",I6,IF(IFERROR(INDEX(Presets!$I$2:$I$200,MATCH($B6,Presets!$A$2:$A$200,0))&"","")="NONE","NONE",IF(IFERROR(INDEX(Presets!$I$2:$I$200,MATCH($B6,Presets!$A$2:$A$200,0))&"","")<>"",VALUE(IFERROR(INDEX(Presets!$I$2:$I$200,MATCH($B6,Presets!$A$2:$A$200,0))&"","")),""))),"INVALID") | V6: =IFERROR(IF(J6<>"",J6,IF(IFERROR(INDEX(Presets!$J$2:$J$200,MATCH($B6,Presets!$A$2:$A$200,0))&"","")<>"",VALUE(IFERROR(INDEX(Presets!$J$2:$J$200,MATCH($B6,Presets!$A$2:$A$200,0))&"","")),"")),"INVALID") | W6: =IFERROR(IF(AND(A6="",B6=""),"",IF(OR(A6="",B6="",P6="",Q6="",R6="",S6="",T6="",U6="",V6="",K6="",AND(U6<>"NONE",L6="")),"INCOMPLETE",IF(OR(COUNTIFS($A$2:$A$11,A6)>1,AND(P6<>"static",P6<>"eod_trailing",P6<>"intraday_trailing"),NOT(ISNUMBER(Q6)),Q6<=0,ROUND(Q6*100,6)<>INT(ROUND(Q6*100,6)),NOT(ISNUMBER(R6)),R6<=0,ROUND(R6*100,6)<>INT(ROUND(R6*100,6)),AND(S6<>"NONE",NOT(ISNUMBER(S6))),AND(P6="static",S6<>"NONE"),IF(ISNUMBER(S6),ROUND(Q6+S6-(Q6-R6),6)<=0,FALSE),IF(ISNUMBER(S6),OR(S6<-100000000,S6>100000000),FALSE),AND(T6<>TRUE,T6<>FALSE),AND(U6<>"NONE",OR(NOT(ISNUMBER(U6)),U6<=0)),IF(V6="NONE",FALSE,IF(ISNUMBER(V6),OR(V6<0,V6<>INT(V6)),TRUE)),NOT(ISNUMBER(K6)),AND(U6<>"NONE",NOT(ISNUMBER(L6))),Q6>100000000,R6>100000000,K6<=0,K6>100000000,IF(ISNUMBER(U6),U6>100000000,FALSE),IF(ISNUMBER(L6),OR(L6<=0,L6>100000000),FALSE)),"INVALID",IF(COUNTIFS('Daily Log'!$A$2:$A$1001,A6,'Daily Log'!$I$2:$I$1001,"INVALID")>0,"INVALID",IF(OR(COUNTIFS('Daily Log'!$A$2:$A$1001,A6,'Daily Log'!$I$2:$I$1001,"INCOMPLETE")>0,COUNTIFS('Daily Log'!$I$2:$I$1001,"UNKNOWN_ACCOUNT")>0),"INCOMPLETE","OK"))))),"INVALID") | X6: =IFERROR(IF($W6<>"OK",$W6,IF(P6="static",Q6,IF(P6="eod_trailing",MAX(Q6,_xlfn.MAXIFS('Daily Log'!$C$2:$C$1001,'Daily Log'!$A$2:$A$1001,A6)),MAX(Q6,K6,_xlfn.MAXIFS('Daily Log'!$C$2:$C$1001,'Daily Log'!$A$2:$A$1001,A6),_xlfn.MAXIFS('Daily Log'!$D$2:$D$1001,'Daily Log'!$A$2:$A$1001,A6))))),"INVALID") | Y6: =IFERROR(IF($W6<>"OK",$W6,-INT(ROUND(-(AJ6)*100,6))/100),"INVALID") | Z6: =IFERROR(IF($W6<>"OK",$W6,AND(ISNUMBER(S6),P6<>"static",ROUND(X6-R6-(Q6+IF(ISNUMBER(S6),S6,0)),6)>=0)),"INVALID") | AA6: =IFERROR(IF($W6<>"OK",$W6,OR(COUNTIFS('Daily Log'!$A$2:$A$1001,A6,'Daily Log'!$I$2:$I$1001,"BREACHED")>0,IF(T6,ROUND(K6-(AJ6),6)<=0,ROUND(K6-(AJ6),6)<0))),"INVALID") | AB6: =IFERROR(IF($W6<>"OK",$W6,IF(AA6,"BREACHED",INT(ROUND((MAX(0,K6-AJ6))*100,6))/100)),"INVALID") | AC6: =IFERROR(IF($W6<>"OK",$W6,IF(AA6,"BREACHED",IF(U6="NONE","NONE",INT(ROUND((MAX(0,U6-MAX(0,-(K6-L6))))*100,6))/100))),"INVALID") | AD6: =IFERROR(IF($W6<>"OK",$W6,IF(AA6,"BREACHED",IF(AC6="NONE",AB6,MIN(AB6,AC6)))),"INVALID") | AE6: =IFERROR(IF($W6<>"OK",$W6,IF(AA6,"BREACHED",IF(AND(AC6<>"NONE",AC6<AB6),"daily_loss","drawdown"))),"INVALID") | AF6: =IFERROR(IF(AK6<>"OK",AK6,IF(AA6,"BREACHED",INT(ROUND((MIN(M6,AD6))*100,6))/100)),"INVALID") | AG6: =IFERROR(IF(AK6<>"OK",AK6,IF(AA6,"BREACHED",IF(V6="NONE",AL6,MIN(AL6,V6)))),"INVALID") | AH6: =IFERROR(IF(AK6<>"OK",AK6,AND(V6<>"NONE",AL6>V6)),"INVALID") | AI6: =IFERROR(IF(AK6<>"OK",AK6,M6>AD6),"INVALID") | AJ6: =IFERROR(IF($W6<>"OK","",IF(P6="static",Q6-R6,IF(S6="NONE",X6-R6,MIN(X6-R6,Q6+S6)))),"INVALID") | AK6: =IFERROR(IF($W6<>"OK",$W6,IF(OR(M6="",N6="",O6=""),"INCOMPLETE",IF(OR(NOT(ISNUMBER(M6)),M6<0,NOT(ISNUMBER(N6)),N6<1,N6<>INT(N6),NOT(ISNUMBER(O6)),O6<=0,O6>100000,ROUND(O6*1000000,3)<>INT(ROUND(O6*1000000,3)),M6>100000000),"INVALID","OK"))),"INVALID") | AL6: =IFERROR(IF(AK6<>"OK","",IF(AA6,0,INT(ROUND(MIN(M6,AD6)/(N6*O6),9)))),"INVALID") | AM6: =IFERROR(IF(AK6<>"OK",AK6,IF(AA6,"BREACHED",INT(ROUND((AG6*N6*O6)*100,6))/100)),"INVALID") | AN6: =IFERROR(IF(AND(A6="",B6=""),"",_xlfn.TEXTJOIN("; ",TRUE,IF(C6="partial","PARTIAL PRESET: verify "&IFERROR(INDEX(Presets!$L$2:$L$200,MATCH($B6,Presets!$A$2:$A$200,0))&"",""),""),IF(C6="manual","MANUAL: all params user-entered",""),IF(OR(AND(D6<>"",IFERROR(INDEX(Presets!$C$2:$C$200,MATCH($B6,Presets!$A$2:$A$200,0))&"","")<>""),AND(E6<>"",IFERROR(INDEX(Presets!$D$2:$D$200,MATCH($B6,Presets!$A$2:$A$200,0))&"","")<>""),AND(F6<>"",IFERROR(INDEX(Presets!$E$2:$E$200,MATCH($B6,Presets!$A$2:$A$200,0))&"","")<>""),AND(G6<>"",IFERROR(INDEX(Presets!$G$2:$G$200,MATCH($B6,Presets!$A$2:$A$200,0))&"","")<>""),AND(H6<>"",IFERROR(INDEX(Presets!$H$2:$H$200,MATCH($B6,Presets!$A$2:$A$200,0))&"","")<>""),AND(I6<>"",IFERROR(INDEX(Presets!$I$2:$I$200,MATCH($B6,Presets!$A$2:$A$200,0))&"","")<>""),AND(J6<>"",IFERROR(INDEX(Presets!$J$2:$J$200,MATCH($B6,Presets!$A$2:$A$200,0))&"","")<>"")),"OVERRIDES PRESET",""),IF(AND(A6<>"",V6=""),"MAX CONTRACTS MISSING: enter a number or NONE",""),IF(AND(IFERROR(INDEX(Presets!$N$2:$N$200,MATCH($B6,Presets!$A$2:$A$200,0))&"","")<>"",NOT(ISNUMBER($B$13))),"AS-OF DATE MISSING: enter today in B13 (stale check off)",""),IF(AND(IFERROR(INDEX(Presets!$N$2:$N$200,MATCH($B6,Presets!$A$2:$A$200,0))&"","")<>"",ISNUMBER($B$13)),IF($B$13-DATE(VALUE(LEFT(IFERROR(INDEX(Presets!$N$2:$N$200,MATCH($B6,Presets!$A$2:$A$200,0))&"",""),4)),VALUE(MID(IFERROR(INDEX(Presets!$N$2:$N$200,MATCH($B6,Presets!$A$2:$A$200,0))&"",""),6,2)),VALUE(MID(IFERROR(INDEX(Presets!$N$2:$N$200,MATCH($B6,Presets!$A$2:$A$200,0))&"",""),9,2)))>30,"STALE PRESET: checked "&IFERROR(INDEX(Presets!$N$2:$N$200,MATCH($B6,Presets!$A$2:$A$200,0))&"","")&", over 30 days before As of",""),""),IF(IFERROR(INDEX(Presets!$M$2:$M$200,MATCH($B6,Presets!$A$2:$A$200,0))&"","")<>"","source: "&IFERROR(INDEX(Presets!$M$2:$M$200,MATCH($B6,Presets!$A$2:$A$200,0))&"","")&" checked "&IFERROR(INDEX(Presets!$N$2:$N$200,MATCH($B6,Presets!$A$2:$A$200,0))&"",""),""))),"INVALID")
C7: =IFERROR(INDEX(Presets!$B$2:$B$200,MATCH($B7,Presets!$A$2:$A$200,0))&"","") | P7: =IFERROR(IF(D7<>"",D7,IFERROR(INDEX(Presets!$C$2:$C$200,MATCH($B7,Presets!$A$2:$A$200,0))&"","")),"INVALID") | Q7: =IFERROR(IF(E7<>"",E7,IF(IFERROR(INDEX(Presets!$D$2:$D$200,MATCH($B7,Presets!$A$2:$A$200,0))&"","")<>"",VALUE(IFERROR(INDEX(Presets!$D$2:$D$200,MATCH($B7,Presets!$A$2:$A$200,0))&"","")),"")),"INVALID") | R7: =IFERROR(IF(F7<>"",F7,IF(IFERROR(INDEX(Presets!$E$2:$E$200,MATCH($B7,Presets!$A$2:$A$200,0))&"","")<>"",VALUE(IFERROR(INDEX(Presets!$E$2:$E$200,MATCH($B7,Presets!$A$2:$A$200,0))&"","")),IF(AND(IFERROR(INDEX(Presets!$F$2:$F$200,MATCH($B7,Presets!$A$2:$A$200,0))&"","")<>"",ISNUMBER(Q7)),VALUE(IFERROR(INDEX(Presets!$F$2:$F$200,MATCH($B7,Presets!$A$2:$A$200,0))&"",""))/100*Q7,""))),"INVALID") | S7: =IFERROR(IF(G7<>"",G7,IF(IFERROR(INDEX(Presets!$G$2:$G$200,MATCH($B7,Presets!$A$2:$A$200,0))&"","")="NONE","NONE",IF(IFERROR(INDEX(Presets!$G$2:$G$200,MATCH($B7,Presets!$A$2:$A$200,0))&"","")<>"",VALUE(IFERROR(INDEX(Presets!$G$2:$G$200,MATCH($B7,Presets!$A$2:$A$200,0))&"","")),""))),"INVALID") | T7: =IFERROR(IF(H7<>"",H7,IF(IFERROR(INDEX(Presets!$H$2:$H$200,MATCH($B7,Presets!$A$2:$A$200,0))&"","")="TRUE",TRUE,IF(IFERROR(INDEX(Presets!$H$2:$H$200,MATCH($B7,Presets!$A$2:$A$200,0))&"","")="FALSE",FALSE,""))),"INVALID") | U7: =IFERROR(IF(I7<>"",I7,IF(IFERROR(INDEX(Presets!$I$2:$I$200,MATCH($B7,Presets!$A$2:$A$200,0))&"","")="NONE","NONE",IF(IFERROR(INDEX(Presets!$I$2:$I$200,MATCH($B7,Presets!$A$2:$A$200,0))&"","")<>"",VALUE(IFERROR(INDEX(Presets!$I$2:$I$200,MATCH($B7,Presets!$A$2:$A$200,0))&"","")),""))),"INVALID") | V7: =IFERROR(IF(J7<>"",J7,IF(IFERROR(INDEX(Presets!$J$2:$J$200,MATCH($B7,Presets!$A$2:$A$200,0))&"","")<>"",VALUE(IFERROR(INDEX(Presets!$J$2:$J$200,MATCH($B7,Presets!$A$2:$A$200,0))&"","")),"")),"INVALID") | W7: =IFERROR(IF(AND(A7="",B7=""),"",IF(OR(A7="",B7="",P7="",Q7="",R7="",S7="",T7="",U7="",V7="",K7="",AND(U7<>"NONE",L7="")),"INCOMPLETE",IF(OR(COUNTIFS($A$2:$A$11,A7)>1,AND(P7<>"static",P7<>"eod_trailing",P7<>"intraday_trailing"),NOT(ISNUMBER(Q7)),Q7<=0,ROUND(Q7*100,6)<>INT(ROUND(Q7*100,6)),NOT(ISNUMBER(R7)),R7<=0,ROUND(R7*100,6)<>INT(ROUND(R7*100,6)),AND(S7<>"NONE",NOT(ISNUMBER(S7))),AND(P7="static",S7<>"NONE"),IF(ISNUMBER(S7),ROUND(Q7+S7-(Q7-R7),6)<=0,FALSE),IF(ISNUMBER(S7),OR(S7<-100000000,S7>100000000),FALSE),AND(T7<>TRUE,T7<>FALSE),AND(U7<>"NONE",OR(NOT(ISNUMBER(U7)),U7<=0)),IF(V7="NONE",FALSE,IF(ISNUMBER(V7),OR(V7<0,V7<>INT(V7)),TRUE)),NOT(ISNUMBER(K7)),AND(U7<>"NONE",NOT(ISNUMBER(L7))),Q7>100000000,R7>100000000,K7<=0,K7>100000000,IF(ISNUMBER(U7),U7>100000000,FALSE),IF(ISNUMBER(L7),OR(L7<=0,L7>100000000),FALSE)),"INVALID",IF(COUNTIFS('Daily Log'!$A$2:$A$1001,A7,'Daily Log'!$I$2:$I$1001,"INVALID")>0,"INVALID",IF(OR(COUNTIFS('Daily Log'!$A$2:$A$1001,A7,'Daily Log'!$I$2:$I$1001,"INCOMPLETE")>0,COUNTIFS('Daily Log'!$I$2:$I$1001,"UNKNOWN_ACCOUNT")>0),"INCOMPLETE","OK"))))),"INVALID") | X7: =IFERROR(IF($W7<>"OK",$W7,IF(P7="static",Q7,IF(P7="eod_trailing",MAX(Q7,_xlfn.MAXIFS('Daily Log'!$C$2:$C$1001,'Daily Log'!$A$2:$A$1001,A7)),MAX(Q7,K7,_xlfn.MAXIFS('Daily Log'!$C$2:$C$1001,'Daily Log'!$A$2:$A$1001,A7),_xlfn.MAXIFS('Daily Log'!$D$2:$D$1001,'Daily Log'!$A$2:$A$1001,A7))))),"INVALID") | Y7: =IFERROR(IF($W7<>"OK",$W7,-INT(ROUND(-(AJ7)*100,6))/100),"INVALID") | Z7: =IFERROR(IF($W7<>"OK",$W7,AND(ISNUMBER(S7),P7<>"static",ROUND(X7-R7-(Q7+IF(ISNUMBER(S7),S7,0)),6)>=0)),"INVALID") | AA7: =IFERROR(IF($W7<>"OK",$W7,OR(COUNTIFS('Daily Log'!$A$2:$A$1001,A7,'Daily Log'!$I$2:$I$1001,"BREACHED")>0,IF(T7,ROUND(K7-(AJ7),6)<=0,ROUND(K7-(AJ7),6)<0))),"INVALID") | AB7: =IFERROR(IF($W7<>"OK",$W7,IF(AA7,"BREACHED",INT(ROUND((MAX(0,K7-AJ7))*100,6))/100)),"INVALID") | AC7: =IFERROR(IF($W7<>"OK",$W7,IF(AA7,"BREACHED",IF(U7="NONE","NONE",INT(ROUND((MAX(0,U7-MAX(0,-(K7-L7))))*100,6))/100))),"INVALID") | AD7: =IFERROR(IF($W7<>"OK",$W7,IF(AA7,"BREACHED",IF(AC7="NONE",AB7,MIN(AB7,AC7)))),"INVALID") | AE7: =IFERROR(IF($W7<>"OK",$W7,IF(AA7,"BREACHED",IF(AND(AC7<>"NONE",AC7<AB7),"daily_loss","drawdown"))),"INVALID") | AF7: =IFERROR(IF(AK7<>"OK",AK7,IF(AA7,"BREACHED",INT(ROUND((MIN(M7,AD7))*100,6))/100)),"INVALID") | AG7: =IFERROR(IF(AK7<>"OK",AK7,IF(AA7,"BREACHED",IF(V7="NONE",AL7,MIN(AL7,V7)))),"INVALID") | AH7: =IFERROR(IF(AK7<>"OK",AK7,AND(V7<>"NONE",AL7>V7)),"INVALID") | AI7: =IFERROR(IF(AK7<>"OK",AK7,M7>AD7),"INVALID") | AJ7: =IFERROR(IF($W7<>"OK","",IF(P7="static",Q7-R7,IF(S7="NONE",X7-R7,MIN(X7-R7,Q7+S7)))),"INVALID") | AK7: =IFERROR(IF($W7<>"OK",$W7,IF(OR(M7="",N7="",O7=""),"INCOMPLETE",IF(OR(NOT(ISNUMBER(M7)),M7<0,NOT(ISNUMBER(N7)),N7<1,N7<>INT(N7),NOT(ISNUMBER(O7)),O7<=0,O7>100000,ROUND(O7*1000000,3)<>INT(ROUND(O7*1000000,3)),M7>100000000),"INVALID","OK"))),"INVALID") | AL7: =IFERROR(IF(AK7<>"OK","",IF(AA7,0,INT(ROUND(MIN(M7,AD7)/(N7*O7),9)))),"INVALID") | AM7: =IFERROR(IF(AK7<>"OK",AK7,IF(AA7,"BREACHED",INT(ROUND((AG7*N7*O7)*100,6))/100)),"INVALID") | AN7: =IFERROR(IF(AND(A7="",B7=""),"",_xlfn.TEXTJOIN("; ",TRUE,IF(C7="partial","PARTIAL PRESET: verify "&IFERROR(INDEX(Presets!$L$2:$L$200,MATCH($B7,Presets!$A$2:$A$200,0))&"",""),""),IF(C7="manual","MANUAL: all params user-entered",""),IF(OR(AND(D7<>"",IFERROR(INDEX(Presets!$C$2:$C$200,MATCH($B7,Presets!$A$2:$A$200,0))&"","")<>""),AND(E7<>"",IFERROR(INDEX(Presets!$D$2:$D$200,MATCH($B7,Presets!$A$2:$A$200,0))&"","")<>""),AND(F7<>"",IFERROR(INDEX(Presets!$E$2:$E$200,MATCH($B7,Presets!$A$2:$A$200,0))&"","")<>""),AND(G7<>"",IFERROR(INDEX(Presets!$G$2:$G$200,MATCH($B7,Presets!$A$2:$A$200,0))&"","")<>""),AND(H7<>"",IFERROR(INDEX(Presets!$H$2:$H$200,MATCH($B7,Presets!$A$2:$A$200,0))&"","")<>""),AND(I7<>"",IFERROR(INDEX(Presets!$I$2:$I$200,MATCH($B7,Presets!$A$2:$A$200,0))&"","")<>""),AND(J7<>"",IFERROR(INDEX(Presets!$J$2:$J$200,MATCH($B7,Presets!$A$2:$A$200,0))&"","")<>"")),"OVERRIDES PRESET",""),IF(AND(A7<>"",V7=""),"MAX CONTRACTS MISSING: enter a number or NONE",""),IF(AND(IFERROR(INDEX(Presets!$N$2:$N$200,MATCH($B7,Presets!$A$2:$A$200,0))&"","")<>"",NOT(ISNUMBER($B$13))),"AS-OF DATE MISSING: enter today in B13 (stale check off)",""),IF(AND(IFERROR(INDEX(Presets!$N$2:$N$200,MATCH($B7,Presets!$A$2:$A$200,0))&"","")<>"",ISNUMBER($B$13)),IF($B$13-DATE(VALUE(LEFT(IFERROR(INDEX(Presets!$N$2:$N$200,MATCH($B7,Presets!$A$2:$A$200,0))&"",""),4)),VALUE(MID(IFERROR(INDEX(Presets!$N$2:$N$200,MATCH($B7,Presets!$A$2:$A$200,0))&"",""),6,2)),VALUE(MID(IFERROR(INDEX(Presets!$N$2:$N$200,MATCH($B7,Presets!$A$2:$A$200,0))&"",""),9,2)))>30,"STALE PRESET: checked "&IFERROR(INDEX(Presets!$N$2:$N$200,MATCH($B7,Presets!$A$2:$A$200,0))&"","")&", over 30 days before As of",""),""),IF(IFERROR(INDEX(Presets!$M$2:$M$200,MATCH($B7,Presets!$A$2:$A$200,0))&"","")<>"","source: "&IFERROR(INDEX(Presets!$M$2:$M$200,MATCH($B7,Presets!$A$2:$A$200,0))&"","")&" checked "&IFERROR(INDEX(Presets!$N$2:$N$200,MATCH($B7,Presets!$A$2:$A$200,0))&"",""),""))),"INVALID")
C8: =IFERROR(INDEX(Presets!$B$2:$B$200,MATCH($B8,Presets!$A$2:$A$200,0))&"","") | P8: =IFERROR(IF(D8<>"",D8,IFERROR(INDEX(Presets!$C$2:$C$200,MATCH($B8,Presets!$A$2:$A$200,0))&"","")),"INVALID") | Q8: =IFERROR(IF(E8<>"",E8,IF(IFERROR(INDEX(Presets!$D$2:$D$200,MATCH($B8,Presets!$A$2:$A$200,0))&"","")<>"",VALUE(IFERROR(INDEX(Presets!$D$2:$D$200,MATCH($B8,Presets!$A$2:$A$200,0))&"","")),"")),"INVALID") | R8: =IFERROR(IF(F8<>"",F8,IF(IFERROR(INDEX(Presets!$E$2:$E$200,MATCH($B8,Presets!$A$2:$A$200,0))&"","")<>"",VALUE(IFERROR(INDEX(Presets!$E$2:$E$200,MATCH($B8,Presets!$A$2:$A$200,0))&"","")),IF(AND(IFERROR(INDEX(Presets!$F$2:$F$200,MATCH($B8,Presets!$A$2:$A$200,0))&"","")<>"",ISNUMBER(Q8)),VALUE(IFERROR(INDEX(Presets!$F$2:$F$200,MATCH($B8,Presets!$A$2:$A$200,0))&"",""))/100*Q8,""))),"INVALID") | S8: =IFERROR(IF(G8<>"",G8,IF(IFERROR(INDEX(Presets!$G$2:$G$200,MATCH($B8,Presets!$A$2:$A$200,0))&"","")="NONE","NONE",IF(IFERROR(INDEX(Presets!$G$2:$G$200,MATCH($B8,Presets!$A$2:$A$200,0))&"","")<>"",VALUE(IFERROR(INDEX(Presets!$G$2:$G$200,MATCH($B8,Presets!$A$2:$A$200,0))&"","")),""))),"INVALID") | T8: =IFERROR(IF(H8<>"",H8,IF(IFERROR(INDEX(Presets!$H$2:$H$200,MATCH($B8,Presets!$A$2:$A$200,0))&"","")="TRUE",TRUE,IF(IFERROR(INDEX(Presets!$H$2:$H$200,MATCH($B8,Presets!$A$2:$A$200,0))&"","")="FALSE",FALSE,""))),"INVALID") | U8: =IFERROR(IF(I8<>"",I8,IF(IFERROR(INDEX(Presets!$I$2:$I$200,MATCH($B8,Presets!$A$2:$A$200,0))&"","")="NONE","NONE",IF(IFERROR(INDEX(Presets!$I$2:$I$200,MATCH($B8,Presets!$A$2:$A$200,0))&"","")<>"",VALUE(IFERROR(INDEX(Presets!$I$2:$I$200,MATCH($B8,Presets!$A$2:$A$200,0))&"","")),""))),"INVALID") | V8: =IFERROR(IF(J8<>"",J8,IF(IFERROR(INDEX(Presets!$J$2:$J$200,MATCH($B8,Presets!$A$2:$A$200,0))&"","")<>"",VALUE(IFERROR(INDEX(Presets!$J$2:$J$200,MATCH($B8,Presets!$A$2:$A$200,0))&"","")),"")),"INVALID") | W8: =IFERROR(IF(AND(A8="",B8=""),"",IF(OR(A8="",B8="",P8="",Q8="",R8="",S8="",T8="",U8="",V8="",K8="",AND(U8<>"NONE",L8="")),"INCOMPLETE",IF(OR(COUNTIFS($A$2:$A$11,A8)>1,AND(P8<>"static",P8<>"eod_trailing",P8<>"intraday_trailing"),NOT(ISNUMBER(Q8)),Q8<=0,ROUND(Q8*100,6)<>INT(ROUND(Q8*100,6)),NOT(ISNUMBER(R8)),R8<=0,ROUND(R8*100,6)<>INT(ROUND(R8*100,6)),AND(S8<>"NONE",NOT(ISNUMBER(S8))),AND(P8="static",S8<>"NONE"),IF(ISNUMBER(S8),ROUND(Q8+S8-(Q8-R8),6)<=0,FALSE),IF(ISNUMBER(S8),OR(S8<-100000000,S8>100000000),FALSE),AND(T8<>TRUE,T8<>FALSE),AND(U8<>"NONE",OR(NOT(ISNUMBER(U8)),U8<=0)),IF(V8="NONE",FALSE,IF(ISNUMBER(V8),OR(V8<0,V8<>INT(V8)),TRUE)),NOT(ISNUMBER(K8)),AND(U8<>"NONE",NOT(ISNUMBER(L8))),Q8>100000000,R8>100000000,K8<=0,K8>100000000,IF(ISNUMBER(U8),U8>100000000,FALSE),IF(ISNUMBER(L8),OR(L8<=0,L8>100000000),FALSE)),"INVALID",IF(COUNTIFS('Daily Log'!$A$2:$A$1001,A8,'Daily Log'!$I$2:$I$1001,"INVALID")>0,"INVALID",IF(OR(COUNTIFS('Daily Log'!$A$2:$A$1001,A8,'Daily Log'!$I$2:$I$1001,"INCOMPLETE")>0,COUNTIFS('Daily Log'!$I$2:$I$1001,"UNKNOWN_ACCOUNT")>0),"INCOMPLETE","OK"))))),"INVALID") | X8: =IFERROR(IF($W8<>"OK",$W8,IF(P8="static",Q8,IF(P8="eod_trailing",MAX(Q8,_xlfn.MAXIFS('Daily Log'!$C$2:$C$1001,'Daily Log'!$A$2:$A$1001,A8)),MAX(Q8,K8,_xlfn.MAXIFS('Daily Log'!$C$2:$C$1001,'Daily Log'!$A$2:$A$1001,A8),_xlfn.MAXIFS('Daily Log'!$D$2:$D$1001,'Daily Log'!$A$2:$A$1001,A8))))),"INVALID") | Y8: =IFERROR(IF($W8<>"OK",$W8,-INT(ROUND(-(AJ8)*100,6))/100),"INVALID") | Z8: =IFERROR(IF($W8<>"OK",$W8,AND(ISNUMBER(S8),P8<>"static",ROUND(X8-R8-(Q8+IF(ISNUMBER(S8),S8,0)),6)>=0)),"INVALID") | AA8: =IFERROR(IF($W8<>"OK",$W8,OR(COUNTIFS('Daily Log'!$A$2:$A$1001,A8,'Daily Log'!$I$2:$I$1001,"BREACHED")>0,IF(T8,ROUND(K8-(AJ8),6)<=0,ROUND(K8-(AJ8),6)<0))),"INVALID") | AB8: =IFERROR(IF($W8<>"OK",$W8,IF(AA8,"BREACHED",INT(ROUND((MAX(0,K8-AJ8))*100,6))/100)),"INVALID") | AC8: =IFERROR(IF($W8<>"OK",$W8,IF(AA8,"BREACHED",IF(U8="NONE","NONE",INT(ROUND((MAX(0,U8-MAX(0,-(K8-L8))))*100,6))/100))),"INVALID") | AD8: =IFERROR(IF($W8<>"OK",$W8,IF(AA8,"BREACHED",IF(AC8="NONE",AB8,MIN(AB8,AC8)))),"INVALID") | AE8: =IFERROR(IF($W8<>"OK",$W8,IF(AA8,"BREACHED",IF(AND(AC8<>"NONE",AC8<AB8),"daily_loss","drawdown"))),"INVALID") | AF8: =IFERROR(IF(AK8<>"OK",AK8,IF(AA8,"BREACHED",INT(ROUND((MIN(M8,AD8))*100,6))/100)),"INVALID") | AG8: =IFERROR(IF(AK8<>"OK",AK8,IF(AA8,"BREACHED",IF(V8="NONE",AL8,MIN(AL8,V8)))),"INVALID") | AH8: =IFERROR(IF(AK8<>"OK",AK8,AND(V8<>"NONE",AL8>V8)),"INVALID") | AI8: =IFERROR(IF(AK8<>"OK",AK8,M8>AD8),"INVALID") | AJ8: =IFERROR(IF($W8<>"OK","",IF(P8="static",Q8-R8,IF(S8="NONE",X8-R8,MIN(X8-R8,Q8+S8)))),"INVALID") | AK8: =IFERROR(IF($W8<>"OK",$W8,IF(OR(M8="",N8="",O8=""),"INCOMPLETE",IF(OR(NOT(ISNUMBER(M8)),M8<0,NOT(ISNUMBER(N8)),N8<1,N8<>INT(N8),NOT(ISNUMBER(O8)),O8<=0,O8>100000,ROUND(O8*1000000,3)<>INT(ROUND(O8*1000000,3)),M8>100000000),"INVALID","OK"))),"INVALID") | AL8: =IFERROR(IF(AK8<>"OK","",IF(AA8,0,INT(ROUND(MIN(M8,AD8)/(N8*O8),9)))),"INVALID") | AM8: =IFERROR(IF(AK8<>"OK",AK8,IF(AA8,"BREACHED",INT(ROUND((AG8*N8*O8)*100,6))/100)),"INVALID") | AN8: =IFERROR(IF(AND(A8="",B8=""),"",_xlfn.TEXTJOIN("; ",TRUE,IF(C8="partial","PARTIAL PRESET: verify "&IFERROR(INDEX(Presets!$L$2:$L$200,MATCH($B8,Presets!$A$2:$A$200,0))&"",""),""),IF(C8="manual","MANUAL: all params user-entered",""),IF(OR(AND(D8<>"",IFERROR(INDEX(Presets!$C$2:$C$200,MATCH($B8,Presets!$A$2:$A$200,0))&"","")<>""),AND(E8<>"",IFERROR(INDEX(Presets!$D$2:$D$200,MATCH($B8,Presets!$A$2:$A$200,0))&"","")<>""),AND(F8<>"",IFERROR(INDEX(Presets!$E$2:$E$200,MATCH($B8,Presets!$A$2:$A$200,0))&"","")<>""),AND(G8<>"",IFERROR(INDEX(Presets!$G$2:$G$200,MATCH($B8,Presets!$A$2:$A$200,0))&"","")<>""),AND(H8<>"",IFERROR(INDEX(Presets!$H$2:$H$200,MATCH($B8,Presets!$A$2:$A$200,0))&"","")<>""),AND(I8<>"",IFERROR(INDEX(Presets!$I$2:$I$200,MATCH($B8,Presets!$A$2:$A$200,0))&"","")<>""),AND(J8<>"",IFERROR(INDEX(Presets!$J$2:$J$200,MATCH($B8,Presets!$A$2:$A$200,0))&"","")<>"")),"OVERRIDES PRESET",""),IF(AND(A8<>"",V8=""),"MAX CONTRACTS MISSING: enter a number or NONE",""),IF(AND(IFERROR(INDEX(Presets!$N$2:$N$200,MATCH($B8,Presets!$A$2:$A$200,0))&"","")<>"",NOT(ISNUMBER($B$13))),"AS-OF DATE MISSING: enter today in B13 (stale check off)",""),IF(AND(IFERROR(INDEX(Presets!$N$2:$N$200,MATCH($B8,Presets!$A$2:$A$200,0))&"","")<>"",ISNUMBER($B$13)),IF($B$13-DATE(VALUE(LEFT(IFERROR(INDEX(Presets!$N$2:$N$200,MATCH($B8,Presets!$A$2:$A$200,0))&"",""),4)),VALUE(MID(IFERROR(INDEX(Presets!$N$2:$N$200,MATCH($B8,Presets!$A$2:$A$200,0))&"",""),6,2)),VALUE(MID(IFERROR(INDEX(Presets!$N$2:$N$200,MATCH($B8,Presets!$A$2:$A$200,0))&"",""),9,2)))>30,"STALE PRESET: checked "&IFERROR(INDEX(Presets!$N$2:$N$200,MATCH($B8,Presets!$A$2:$A$200,0))&"","")&", over 30 days before As of",""),""),IF(IFERROR(INDEX(Presets!$M$2:$M$200,MATCH($B8,Presets!$A$2:$A$200,0))&"","")<>"","source: "&IFERROR(INDEX(Presets!$M$2:$M$200,MATCH($B8,Presets!$A$2:$A$200,0))&"","")&" checked "&IFERROR(INDEX(Presets!$N$2:$N$200,MATCH($B8,Presets!$A$2:$A$200,0))&"",""),""))),"INVALID")
C9: =IFERROR(INDEX(Presets!$B$2:$B$200,MATCH($B9,Presets!$A$2:$A$200,0))&"","") | P9: =IFERROR(IF(D9<>"",D9,IFERROR(INDEX(Presets!$C$2:$C$200,MATCH($B9,Presets!$A$2:$A$200,0))&"","")),"INVALID") | Q9: =IFERROR(IF(E9<>"",E9,IF(IFERROR(INDEX(Presets!$D$2:$D$200,MATCH($B9,Presets!$A$2:$A$200,0))&"","")<>"",VALUE(IFERROR(INDEX(Presets!$D$2:$D$200,MATCH($B9,Presets!$A$2:$A$200,0))&"","")),"")),"INVALID") | R9: =IFERROR(IF(F9<>"",F9,IF(IFERROR(INDEX(Presets!$E$2:$E$200,MATCH($B9,Presets!$A$2:$A$200,0))&"","")<>"",VALUE(IFERROR(INDEX(Presets!$E$2:$E$200,MATCH($B9,Presets!$A$2:$A$200,0))&"","")),IF(AND(IFERROR(INDEX(Presets!$F$2:$F$200,MATCH($B9,Presets!$A$2:$A$200,0))&"","")<>"",ISNUMBER(Q9)),VALUE(IFERROR(INDEX(Presets!$F$2:$F$200,MATCH($B9,Presets!$A$2:$A$200,0))&"",""))/100*Q9,""))),"INVALID") | S9: =IFERROR(IF(G9<>"",G9,IF(IFERROR(INDEX(Presets!$G$2:$G$200,MATCH($B9,Presets!$A$2:$A$200,0))&"","")="NONE","NONE",IF(IFERROR(INDEX(Presets!$G$2:$G$200,MATCH($B9,Presets!$A$2:$A$200,0))&"","")<>"",VALUE(IFERROR(INDEX(Presets!$G$2:$G$200,MATCH($B9,Presets!$A$2:$A$200,0))&"","")),""))),"INVALID") | T9: =IFERROR(IF(H9<>"",H9,IF(IFERROR(INDEX(Presets!$H$2:$H$200,MATCH($B9,Presets!$A$2:$A$200,0))&"","")="TRUE",TRUE,IF(IFERROR(INDEX(Presets!$H$2:$H$200,MATCH($B9,Presets!$A$2:$A$200,0))&"","")="FALSE",FALSE,""))),"INVALID") | U9: =IFERROR(IF(I9<>"",I9,IF(IFERROR(INDEX(Presets!$I$2:$I$200,MATCH($B9,Presets!$A$2:$A$200,0))&"","")="NONE","NONE",IF(IFERROR(INDEX(Presets!$I$2:$I$200,MATCH($B9,Presets!$A$2:$A$200,0))&"","")<>"",VALUE(IFERROR(INDEX(Presets!$I$2:$I$200,MATCH($B9,Presets!$A$2:$A$200,0))&"","")),""))),"INVALID") | V9: =IFERROR(IF(J9<>"",J9,IF(IFERROR(INDEX(Presets!$J$2:$J$200,MATCH($B9,Presets!$A$2:$A$200,0))&"","")<>"",VALUE(IFERROR(INDEX(Presets!$J$2:$J$200,MATCH($B9,Presets!$A$2:$A$200,0))&"","")),"")),"INVALID") | W9: =IFERROR(IF(AND(A9="",B9=""),"",IF(OR(A9="",B9="",P9="",Q9="",R9="",S9="",T9="",U9="",V9="",K9="",AND(U9<>"NONE",L9="")),"INCOMPLETE",IF(OR(COUNTIFS($A$2:$A$11,A9)>1,AND(P9<>"static",P9<>"eod_trailing",P9<>"intraday_trailing"),NOT(ISNUMBER(Q9)),Q9<=0,ROUND(Q9*100,6)<>INT(ROUND(Q9*100,6)),NOT(ISNUMBER(R9)),R9<=0,ROUND(R9*100,6)<>INT(ROUND(R9*100,6)),AND(S9<>"NONE",NOT(ISNUMBER(S9))),AND(P9="static",S9<>"NONE"),IF(ISNUMBER(S9),ROUND(Q9+S9-(Q9-R9),6)<=0,FALSE),IF(ISNUMBER(S9),OR(S9<-100000000,S9>100000000),FALSE),AND(T9<>TRUE,T9<>FALSE),AND(U9<>"NONE",OR(NOT(ISNUMBER(U9)),U9<=0)),IF(V9="NONE",FALSE,IF(ISNUMBER(V9),OR(V9<0,V9<>INT(V9)),TRUE)),NOT(ISNUMBER(K9)),AND(U9<>"NONE",NOT(ISNUMBER(L9))),Q9>100000000,R9>100000000,K9<=0,K9>100000000,IF(ISNUMBER(U9),U9>100000000,FALSE),IF(ISNUMBER(L9),OR(L9<=0,L9>100000000),FALSE)),"INVALID",IF(COUNTIFS('Daily Log'!$A$2:$A$1001,A9,'Daily Log'!$I$2:$I$1001,"INVALID")>0,"INVALID",IF(OR(COUNTIFS('Daily Log'!$A$2:$A$1001,A9,'Daily Log'!$I$2:$I$1001,"INCOMPLETE")>0,COUNTIFS('Daily Log'!$I$2:$I$1001,"UNKNOWN_ACCOUNT")>0),"INCOMPLETE","OK"))))),"INVALID") | X9: =IFERROR(IF($W9<>"OK",$W9,IF(P9="static",Q9,IF(P9="eod_trailing",MAX(Q9,_xlfn.MAXIFS('Daily Log'!$C$2:$C$1001,'Daily Log'!$A$2:$A$1001,A9)),MAX(Q9,K9,_xlfn.MAXIFS('Daily Log'!$C$2:$C$1001,'Daily Log'!$A$2:$A$1001,A9),_xlfn.MAXIFS('Daily Log'!$D$2:$D$1001,'Daily Log'!$A$2:$A$1001,A9))))),"INVALID") | Y9: =IFERROR(IF($W9<>"OK",$W9,-INT(ROUND(-(AJ9)*100,6))/100),"INVALID") | Z9: =IFERROR(IF($W9<>"OK",$W9,AND(ISNUMBER(S9),P9<>"static",ROUND(X9-R9-(Q9+IF(ISNUMBER(S9),S9,0)),6)>=0)),"INVALID") | AA9: =IFERROR(IF($W9<>"OK",$W9,OR(COUNTIFS('Daily Log'!$A$2:$A$1001,A9,'Daily Log'!$I$2:$I$1001,"BREACHED")>0,IF(T9,ROUND(K9-(AJ9),6)<=0,ROUND(K9-(AJ9),6)<0))),"INVALID") | AB9: =IFERROR(IF($W9<>"OK",$W9,IF(AA9,"BREACHED",INT(ROUND((MAX(0,K9-AJ9))*100,6))/100)),"INVALID") | AC9: =IFERROR(IF($W9<>"OK",$W9,IF(AA9,"BREACHED",IF(U9="NONE","NONE",INT(ROUND((MAX(0,U9-MAX(0,-(K9-L9))))*100,6))/100))),"INVALID") | AD9: =IFERROR(IF($W9<>"OK",$W9,IF(AA9,"BREACHED",IF(AC9="NONE",AB9,MIN(AB9,AC9)))),"INVALID") | AE9: =IFERROR(IF($W9<>"OK",$W9,IF(AA9,"BREACHED",IF(AND(AC9<>"NONE",AC9<AB9),"daily_loss","drawdown"))),"INVALID") | AF9: =IFERROR(IF(AK9<>"OK",AK9,IF(AA9,"BREACHED",INT(ROUND((MIN(M9,AD9))*100,6))/100)),"INVALID") | AG9: =IFERROR(IF(AK9<>"OK",AK9,IF(AA9,"BREACHED",IF(V9="NONE",AL9,MIN(AL9,V9)))),"INVALID") | AH9: =IFERROR(IF(AK9<>"OK",AK9,AND(V9<>"NONE",AL9>V9)),"INVALID") | AI9: =IFERROR(IF(AK9<>"OK",AK9,M9>AD9),"INVALID") | AJ9: =IFERROR(IF($W9<>"OK","",IF(P9="static",Q9-R9,IF(S9="NONE",X9-R9,MIN(X9-R9,Q9+S9)))),"INVALID") | AK9: =IFERROR(IF($W9<>"OK",$W9,IF(OR(M9="",N9="",O9=""),"INCOMPLETE",IF(OR(NOT(ISNUMBER(M9)),M9<0,NOT(ISNUMBER(N9)),N9<1,N9<>INT(N9),NOT(ISNUMBER(O9)),O9<=0,O9>100000,ROUND(O9*1000000,3)<>INT(ROUND(O9*1000000,3)),M9>100000000),"INVALID","OK"))),"INVALID") | AL9: =IFERROR(IF(AK9<>"OK","",IF(AA9,0,INT(ROUND(MIN(M9,AD9)/(N9*O9),9)))),"INVALID") | AM9: =IFERROR(IF(AK9<>"OK",AK9,IF(AA9,"BREACHED",INT(ROUND((AG9*N9*O9)*100,6))/100)),"INVALID") | AN9: =IFERROR(IF(AND(A9="",B9=""),"",_xlfn.TEXTJOIN("; ",TRUE,IF(C9="partial","PARTIAL PRESET: verify "&IFERROR(INDEX(Presets!$L$2:$L$200,MATCH($B9,Presets!$A$2:$A$200,0))&"",""),""),IF(C9="manual","MANUAL: all params user-entered",""),IF(OR(AND(D9<>"",IFERROR(INDEX(Presets!$C$2:$C$200,MATCH($B9,Presets!$A$2:$A$200,0))&"","")<>""),AND(E9<>"",IFERROR(INDEX(Presets!$D$2:$D$200,MATCH($B9,Presets!$A$2:$A$200,0))&"","")<>""),AND(F9<>"",IFERROR(INDEX(Presets!$E$2:$E$200,MATCH($B9,Presets!$A$2:$A$200,0))&"","")<>""),AND(G9<>"",IFERROR(INDEX(Presets!$G$2:$G$200,MATCH($B9,Presets!$A$2:$A$200,0))&"","")<>""),AND(H9<>"",IFERROR(INDEX(Presets!$H$2:$H$200,MATCH($B9,Presets!$A$2:$A$200,0))&"","")<>""),AND(I9<>"",IFERROR(INDEX(Presets!$I$2:$I$200,MATCH($B9,Presets!$A$2:$A$200,0))&"","")<>""),AND(J9<>"",IFERROR(INDEX(Presets!$J$2:$J$200,MATCH($B9,Presets!$A$2:$A$200,0))&"","")<>"")),"OVERRIDES PRESET",""),IF(AND(A9<>"",V9=""),"MAX CONTRACTS MISSING: enter a number or NONE",""),IF(AND(IFERROR(INDEX(Presets!$N$2:$N$200,MATCH($B9,Presets!$A$2:$A$200,0))&"","")<>"",NOT(ISNUMBER($B$13))),"AS-OF DATE MISSING: enter today in B13 (stale check off)",""),IF(AND(IFERROR(INDEX(Presets!$N$2:$N$200,MATCH($B9,Presets!$A$2:$A$200,0))&"","")<>"",ISNUMBER($B$13)),IF($B$13-DATE(VALUE(LEFT(IFERROR(INDEX(Presets!$N$2:$N$200,MATCH($B9,Presets!$A$2:$A$200,0))&"",""),4)),VALUE(MID(IFERROR(INDEX(Presets!$N$2:$N$200,MATCH($B9,Presets!$A$2:$A$200,0))&"",""),6,2)),VALUE(MID(IFERROR(INDEX(Presets!$N$2:$N$200,MATCH($B9,Presets!$A$2:$A$200,0))&"",""),9,2)))>30,"STALE PRESET: checked "&IFERROR(INDEX(Presets!$N$2:$N$200,MATCH($B9,Presets!$A$2:$A$200,0))&"","")&", over 30 days before As of",""),""),IF(IFERROR(INDEX(Presets!$M$2:$M$200,MATCH($B9,Presets!$A$2:$A$200,0))&"","")<>"","source: "&IFERROR(INDEX(Presets!$M$2:$M$200,MATCH($B9,Presets!$A$2:$A$200,0))&"","")&" checked "&IFERROR(INDEX(Presets!$N$2:$N$200,MATCH($B9,Presets!$A$2:$A$200,0))&"",""),""))),"INVALID")
